2018-07-05 14:59:56,236 ERROR: Exception on /index [GET] [in d:\python_projects\flask\venv\lib\site-packages\flask\app.py:1761]
Traceback (most recent call last):
  File "d:\python_projects\flask\venv\lib\site-packages\flask\app.py", line 2292, in wsgi_app
    response = self.full_dispatch_request()
  File "d:\python_projects\flask\venv\lib\site-packages\flask\app.py", line 1815, in full_dispatch_request
    rv = self.handle_user_exception(e)
  File "d:\python_projects\flask\venv\lib\site-packages\flask\app.py", line 1718, in handle_user_exception
    reraise(exc_type, exc_value, tb)
  File "d:\python_projects\flask\venv\lib\site-packages\flask\_compat.py", line 35, in reraise
    raise value
  File "d:\python_projects\flask\venv\lib\site-packages\flask\app.py", line 1813, in full_dispatch_request
    rv = self.dispatch_request()
  File "d:\python_projects\flask\venv\lib\site-packages\flask\app.py", line 1799, in dispatch_request
    return self.view_functions[rule.endpoint](**req.view_args)
  File "d:\python_projects\flask\venv\lib\site-packages\flask_login\utils.py", line 261, in decorated_view
    return func(*args, **kwargs)
  File "D:\python_projects\flask\app\main\routes.py", line 37, in index
    next_url=next_url, prev_url=prev_url)
  File "d:\python_projects\flask\venv\lib\site-packages\flask\templating.py", line 135, in render_template
    context, ctx.app)
  File "d:\python_projects\flask\venv\lib\site-packages\flask\templating.py", line 117, in _render
    rv = template.render(context)
  File "d:\python_projects\flask\venv\lib\site-packages\jinja2\asyncsupport.py", line 76, in render
    return original_render(self, *args, **kwargs)
  File "d:\python_projects\flask\venv\lib\site-packages\jinja2\environment.py", line 1008, in render
    return self.environment.handle_exception(exc_info, True)
  File "d:\python_projects\flask\venv\lib\site-packages\jinja2\environment.py", line 780, in handle_exception
    reraise(exc_type, exc_value, tb)
  File "d:\python_projects\flask\venv\lib\site-packages\jinja2\_compat.py", line 37, in reraise
    raise value.with_traceback(tb)
  File "D:\python_projects\flask\app\templates\index.html", line 2, in top-level template code
    {% import 'bootstrap/wtf.html' as wtf %}
  File "D:\python_projects\flask\app\templates\base.html", line 1, in top-level template code
    {% extends 'bootstrap/base.html' %}
  File "d:\python_projects\flask\venv\lib\site-packages\flask_bootstrap\templates\bootstrap\base.html", line 1, in top-level template code
    {% block doc -%}
  File "d:\python_projects\flask\venv\lib\site-packages\flask_bootstrap\templates\bootstrap\base.html", line 4, in block "doc"
    {%- block html %}
  File "d:\python_projects\flask\venv\lib\site-packages\flask_bootstrap\templates\bootstrap\base.html", line 20, in block "html"
    {% block body -%}
  File "d:\python_projects\flask\venv\lib\site-packages\flask_bootstrap\templates\bootstrap\base.html", line 23, in block "body"
    {% block content -%}
  File "D:\python_projects\flask\app\templates\base.html", line 49, in block "content"
    {% block app_content %}{% endblock %}
  File "D:\python_projects\flask\app\templates\index.html", line 11, in block "app_content"
    {% include '_post.html' %}
  File "D:\python_projects\flask\app\templates\_post.html", line 4, in top-level template code
    <a href="{{ url_for('user', username=post.author.username) }}">
  File "d:\python_projects\flask\venv\lib\site-packages\flask\helpers.py", line 356, in url_for
    return appctx.app.handle_url_build_error(error, endpoint, values)
  File "d:\python_projects\flask\venv\lib\site-packages\flask\app.py", line 2061, in handle_url_build_error
    reraise(exc_type, exc_value, tb)
  File "d:\python_projects\flask\venv\lib\site-packages\flask\_compat.py", line 35, in reraise
    raise value
  File "d:\python_projects\flask\venv\lib\site-packages\flask\helpers.py", line 345, in url_for
    force_external=external)
  File "d:\python_projects\flask\venv\lib\site-packages\werkzeug\routing.py", line 1776, in build
    raise BuildError(endpoint, values, method, self)
werkzeug.routing.BuildError: Could not build url for endpoint 'user' with values ['username']. Did you mean 'main.user' instead?
2018-07-06 19:20:06,694 INFO: Microblog startup [in D:\python_projects\flask\app\__init__.py:73]
2018-07-06 19:20:14,967 INFO: Microblog startup [in D:\python_projects\flask\app\__init__.py:73]
2018-07-06 19:20:36,632 INFO: Microblog startup [in D:\python_projects\flask\app\__init__.py:73]
2018-07-06 23:22:38,005 INFO: Microblog startup [in D:\python_projects\flask\app\__init__.py:73]
2018-07-06 23:23:28,229 INFO: Microblog startup [in D:\python_projects\flask\app\__init__.py:73]
2018-07-06 23:24:15,763 INFO: Microblog startup [in D:\python_projects\flask\app\__init__.py:73]
2018-07-06 23:25:57,208 INFO: Microblog startup [in D:\python_projects\flask\app\__init__.py:73]
2018-07-06 23:25:57,214 INFO: Microblog startup [in D:\python_projects\flask\app\__init__.py:73]
2018-07-06 23:25:57,214 INFO: Microblog startup [in D:\python_projects\flask\app\__init__.py:73]
2018-07-06 23:25:57,219 INFO: Microblog startup [in D:\python_projects\flask\app\__init__.py:73]
2018-07-06 23:25:57,219 INFO: Microblog startup [in D:\python_projects\flask\app\__init__.py:73]
2018-07-06 23:25:57,219 INFO: Microblog startup [in D:\python_projects\flask\app\__init__.py:73]
2018-07-06 23:25:57,224 INFO: Microblog startup [in D:\python_projects\flask\app\__init__.py:73]
2018-07-06 23:25:57,224 INFO: Microblog startup [in D:\python_projects\flask\app\__init__.py:73]
2018-07-06 23:25:57,224 INFO: Microblog startup [in D:\python_projects\flask\app\__init__.py:73]
2018-07-06 23:25:57,224 INFO: Microblog startup [in D:\python_projects\flask\app\__init__.py:73]
2018-07-06 23:27:22,289 INFO: Microblog startup [in D:\python_projects\flask\app\__init__.py:73]
2018-07-06 23:27:22,316 INFO: Microblog startup [in D:\python_projects\flask\app\__init__.py:73]
2018-07-06 23:27:22,316 INFO: Microblog startup [in D:\python_projects\flask\app\__init__.py:73]
2018-07-06 23:27:22,361 INFO: Microblog startup [in D:\python_projects\flask\app\__init__.py:73]
2018-07-06 23:27:22,361 INFO: Microblog startup [in D:\python_projects\flask\app\__init__.py:73]
2018-07-06 23:27:22,361 INFO: Microblog startup [in D:\python_projects\flask\app\__init__.py:73]
2018-07-06 23:27:22,410 INFO: Microblog startup [in D:\python_projects\flask\app\__init__.py:73]
2018-07-06 23:27:22,410 INFO: Microblog startup [in D:\python_projects\flask\app\__init__.py:73]
2018-07-06 23:27:22,410 INFO: Microblog startup [in D:\python_projects\flask\app\__init__.py:73]
2018-07-06 23:27:22,410 INFO: Microblog startup [in D:\python_projects\flask\app\__init__.py:73]
2018-07-06 23:48:00,905 INFO: Microblog startup [in D:\python_projects\flask\app\__init__.py:73]
2018-07-06 23:48:05,134 INFO: Microblog startup [in D:\python_projects\flask\app\__init__.py:73]
2018-07-11 15:36:46,598 INFO: Microblog startup [in D:\python_projects\flask\app\__init__.py:73]
2018-07-11 15:43:55,652 INFO: Microblog startup [in D:\python_projects\flask\app\__init__.py:73]
2018-07-11 19:58:31,913 INFO: Microblog startup [in D:\python_projects\flask\app\__init__.py:73]
2018-07-11 20:11:47,553 INFO: Microblog startup [in D:\python_projects\flask\app\__init__.py:73]
2018-07-11 20:15:14,294 INFO: Microblog startup [in D:\python_projects\flask\app\__init__.py:73]
2018-07-11 20:15:26,554 ERROR: Exception on /upload [POST] [in d:\python_projects\flask\venv\lib\site-packages\flask\app.py:1761]
Traceback (most recent call last):
  File "d:\python_projects\flask\venv\lib\site-packages\flask\app.py", line 2292, in wsgi_app
    response = self.full_dispatch_request()
  File "d:\python_projects\flask\venv\lib\site-packages\flask\app.py", line 1815, in full_dispatch_request
    rv = self.handle_user_exception(e)
  File "d:\python_projects\flask\venv\lib\site-packages\flask\app.py", line 1718, in handle_user_exception
    reraise(exc_type, exc_value, tb)
  File "d:\python_projects\flask\venv\lib\site-packages\flask\_compat.py", line 35, in reraise
    raise value
  File "d:\python_projects\flask\venv\lib\site-packages\flask\app.py", line 1813, in full_dispatch_request
    rv = self.dispatch_request()
  File "d:\python_projects\flask\venv\lib\site-packages\flask\app.py", line 1799, in dispatch_request
    return self.view_functions[rule.endpoint](**req.view_args)
  File "D:\python_projects\flask\app\main\routes.py", line 145, in upload
    f = os.path.join(os.getcwd(), file.filename)
AttributeError: 'str' object has no attribute 'filename'
2018-07-11 20:16:04,591 ERROR: Exception on /upload [POST] [in d:\python_projects\flask\venv\lib\site-packages\flask\app.py:1761]
Traceback (most recent call last):
  File "d:\python_projects\flask\venv\lib\site-packages\flask\app.py", line 2292, in wsgi_app
    response = self.full_dispatch_request()
  File "d:\python_projects\flask\venv\lib\site-packages\flask\app.py", line 1815, in full_dispatch_request
    rv = self.handle_user_exception(e)
  File "d:\python_projects\flask\venv\lib\site-packages\flask\app.py", line 1718, in handle_user_exception
    reraise(exc_type, exc_value, tb)
  File "d:\python_projects\flask\venv\lib\site-packages\flask\_compat.py", line 35, in reraise
    raise value
  File "d:\python_projects\flask\venv\lib\site-packages\flask\app.py", line 1813, in full_dispatch_request
    rv = self.dispatch_request()
  File "d:\python_projects\flask\venv\lib\site-packages\flask\app.py", line 1799, in dispatch_request
    return self.view_functions[rule.endpoint](**req.view_args)
  File "D:\python_projects\flask\app\main\routes.py", line 145, in upload
    f = os.path.join(os.getcwd(), 'image.png')
AttributeError: 'str' object has no attribute 'filename'
2018-07-11 20:16:20,754 INFO: Microblog startup [in D:\python_projects\flask\app\__init__.py:73]
