2018-07-14 17:51:15,011 ERROR: Exception on /favicon.ico [GET] [in d:\python_projects\flask\venv\lib\site-packages\flask\app.py:1761]
Traceback (most recent call last):
  File "d:\python_projects\flask\venv\lib\site-packages\flask\app.py", line 1813, in full_dispatch_request
    rv = self.dispatch_request()
  File "d:\python_projects\flask\venv\lib\site-packages\flask\app.py", line 1791, in dispatch_request
    self.raise_routing_exception(req)
  File "d:\python_projects\flask\venv\lib\site-packages\flask\app.py", line 1774, in raise_routing_exception
    raise request.routing_exception
  File "d:\python_projects\flask\venv\lib\site-packages\flask\ctx.py", line 336, in match_request
    self.url_adapter.match(return_rule=True)
  File "d:\python_projects\flask\venv\lib\site-packages\werkzeug\routing.py", line 1581, in match
    raise NotFound()
werkzeug.exceptions.NotFound: 404 Not Found: The requested URL was not found on the server.  If you entered the URL manually please check your spelling and try again.

During handling of the above exception, another exception occurred:

Traceback (most recent call last):
  File "d:\python_projects\flask\venv\lib\site-packages\flask\app.py", line 2292, in wsgi_app
    response = self.full_dispatch_request()
  File "d:\python_projects\flask\venv\lib\site-packages\flask\app.py", line 1815, in full_dispatch_request
    rv = self.handle_user_exception(e)
  File "d:\python_projects\flask\venv\lib\site-packages\flask\app.py", line 1713, in handle_user_exception
    return self.handle_http_exception(e)
  File "d:\python_projects\flask\venv\lib\site-packages\flask\app.py", line 1644, in handle_http_exception
    return handler(e)
  File "D:\python_projects\flask\app\errors\handlers.py", line 8, in not_found_error
    return render_template('404.html'), 404
  File "d:\python_projects\flask\venv\lib\site-packages\flask\templating.py", line 135, in render_template
    context, ctx.app)
  File "d:\python_projects\flask\venv\lib\site-packages\flask\templating.py", line 117, in _render
    rv = template.render(context)
  File "d:\python_projects\flask\venv\lib\site-packages\jinja2\asyncsupport.py", line 76, in render
    return original_render(self, *args, **kwargs)
  File "d:\python_projects\flask\venv\lib\site-packages\jinja2\environment.py", line 1008, in render
    return self.environment.handle_exception(exc_info, True)
  File "d:\python_projects\flask\venv\lib\site-packages\jinja2\environment.py", line 780, in handle_exception
    reraise(exc_type, exc_value, tb)
  File "d:\python_projects\flask\venv\lib\site-packages\jinja2\_compat.py", line 37, in reraise
    raise value.with_traceback(tb)
  File "D:\python_projects\flask\app\templates\base.html", line 41, in template
    {% endblock %}
  File "d:\python_projects\flask\venv\lib\site-packages\jinja2\environment.py", line 1005, in render
    return concat(self.root_render_func(self.new_context(vars)))
  File "D:\python_projects\flask\app\templates\404.html", line 1, in top-level template code
    {% extends "base.html" %}
  File "d:\python_projects\flask\venv\lib\site-packages\jinja2\environment.py", line 780, in handle_exception
    reraise(exc_type, exc_value, tb)
  File "d:\python_projects\flask\venv\lib\site-packages\jinja2\_compat.py", line 37, in reraise
    raise value.with_traceback(tb)
  File "D:\python_projects\flask\app\templates\base.html", line 41, in template
    {% endblock %}
  File "d:\python_projects\flask\venv\lib\site-packages\jinja2\environment.py", line 497, in _parse
    return Parser(self, source, name, encode_filename(filename)).parse()
  File "d:\python_projects\flask\venv\lib\site-packages\jinja2\parser.py", line 901, in parse
    result = nodes.Template(self.subparse(), lineno=1)
  File "d:\python_projects\flask\venv\lib\site-packages\jinja2\parser.py", line 883, in subparse
    rv = self.parse_statement()
  File "d:\python_projects\flask\venv\lib\site-packages\jinja2\parser.py", line 130, in parse_statement
    return getattr(self, 'parse_' + self.stream.current.value)()
  File "d:\python_projects\flask\venv\lib\site-packages\jinja2\parser.py", line 268, in parse_block
    node.body = self.parse_statements(('name:endblock',), drop_needle=True)
  File "d:\python_projects\flask\venv\lib\site-packages\jinja2\parser.py", line 165, in parse_statements
    result = self.subparse(end_tokens)
  File "d:\python_projects\flask\venv\lib\site-packages\jinja2\parser.py", line 883, in subparse
    rv = self.parse_statement()
  File "d:\python_projects\flask\venv\lib\site-packages\jinja2\parser.py", line 130, in parse_statement
    return getattr(self, 'parse_' + self.stream.current.value)()
  File "d:\python_projects\flask\venv\lib\site-packages\jinja2\parser.py", line 213, in parse_if
    'name:endif'))
  File "d:\python_projects\flask\venv\lib\site-packages\jinja2\parser.py", line 165, in parse_statements
    result = self.subparse(end_tokens)
  File "d:\python_projects\flask\venv\lib\site-packages\jinja2\parser.py", line 883, in subparse
    rv = self.parse_statement()
  File "d:\python_projects\flask\venv\lib\site-packages\jinja2\parser.py", line 144, in parse_statement
    self.fail_unknown_tag(token.value, token.lineno)
  File "d:\python_projects\flask\venv\lib\site-packages\jinja2\parser.py", line 97, in fail_unknown_tag
    return self._fail_ut_eof(name, self._end_token_stack, lineno)
  File "d:\python_projects\flask\venv\lib\site-packages\jinja2\parser.py", line 90, in _fail_ut_eof
    self.fail(' '.join(message), lineno)
  File "d:\python_projects\flask\venv\lib\site-packages\jinja2\parser.py", line 59, in fail
    raise exc(msg, lineno, self.name, self.filename)
jinja2.exceptions.TemplateSyntaxError: Encountered unknown tag 'endblock'. You probably made a nesting mistake. Jinja is expecting this tag, but currently looking for 'elif' or 'else' or 'endif'. The innermost block that needs to be closed is 'if'.
2018-07-14 17:52:56,757 INFO: Microblog startup [in D:\python_projects\flask\app\__init__.py:76]
2018-07-14 17:53:31,281 ERROR: Exception on /search [GET] [in d:\python_projects\flask\venv\lib\site-packages\flask\app.py:1761]
Traceback (most recent call last):
  File "d:\python_projects\flask\venv\lib\site-packages\flask\app.py", line 2292, in wsgi_app
    response = self.full_dispatch_request()
  File "d:\python_projects\flask\venv\lib\site-packages\flask\app.py", line 1815, in full_dispatch_request
    rv = self.handle_user_exception(e)
  File "d:\python_projects\flask\venv\lib\site-packages\flask\app.py", line 1718, in handle_user_exception
    reraise(exc_type, exc_value, tb)
  File "d:\python_projects\flask\venv\lib\site-packages\flask\_compat.py", line 35, in reraise
    raise value
  File "d:\python_projects\flask\venv\lib\site-packages\flask\app.py", line 1813, in full_dispatch_request
    rv = self.dispatch_request()
  File "d:\python_projects\flask\venv\lib\site-packages\flask\app.py", line 1799, in dispatch_request
    return self.view_functions[rule.endpoint](**req.view_args)
  File "d:\python_projects\flask\venv\lib\site-packages\flask_login\utils.py", line 261, in decorated_view
    return func(*args, **kwargs)
  File "D:\python_projects\flask\app\main\routes.py", line 162, in search
    return render_template('search.html', title=_('Search'), posts=posts,
NameError: name '_' is not defined
2018-07-21 20:57:54,817 INFO: Microblog startup [in D:\python_projects\flask\app\__init__.py:76]
2018-07-21 20:58:08,490 INFO: Microblog startup [in D:\python_projects\flask\app\__init__.py:76]
2018-07-21 20:58:37,232 INFO: Microblog startup [in D:\python_projects\flask\app\__init__.py:76]
