2018-07-05 14:55:09,902 ERROR: Exception on /auth/login [GET] [in d:\python_projects\flask\venv\lib\site-packages\flask\app.py:1761]
Traceback (most recent call last):
  File "d:\python_projects\flask\venv\lib\site-packages\flask\app.py", line 2292, in wsgi_app
    response = self.full_dispatch_request()
  File "d:\python_projects\flask\venv\lib\site-packages\flask\app.py", line 1815, in full_dispatch_request
    rv = self.handle_user_exception(e)
  File "d:\python_projects\flask\venv\lib\site-packages\flask\app.py", line 1718, in handle_user_exception
    reraise(exc_type, exc_value, tb)
  File "d:\python_projects\flask\venv\lib\site-packages\flask\_compat.py", line 35, in reraise
    raise value
  File "d:\python_projects\flask\venv\lib\site-packages\flask\app.py", line 1813, in full_dispatch_request
    rv = self.dispatch_request()
  File "d:\python_projects\flask\venv\lib\site-packages\flask\app.py", line 1799, in dispatch_request
    return self.view_functions[rule.endpoint](**req.view_args)
  File "D:\python_projects\flask\app\auth\routes.py", line 26, in login
    return render_template('login.html', title='Sign in', form=form)
  File "d:\python_projects\flask\venv\lib\site-packages\flask\templating.py", line 134, in render_template
    return _render(ctx.app.jinja_env.get_or_select_template(template_name_or_list),
  File "d:\python_projects\flask\venv\lib\site-packages\jinja2\environment.py", line 869, in get_or_select_template
    return self.get_template(template_name_or_list, parent, globals)
  File "d:\python_projects\flask\venv\lib\site-packages\jinja2\environment.py", line 830, in get_template
    return self._load_template(name, self.make_globals(globals))
  File "d:\python_projects\flask\venv\lib\site-packages\jinja2\environment.py", line 804, in _load_template
    template = self.loader.load(self, name, globals)
  File "d:\python_projects\flask\venv\lib\site-packages\jinja2\loaders.py", line 113, in load
    source, filename, uptodate = self.get_source(environment, name)
  File "d:\python_projects\flask\venv\lib\site-packages\flask\templating.py", line 58, in get_source
    return self._get_source_fast(environment, template)
  File "d:\python_projects\flask\venv\lib\site-packages\flask\templating.py", line 86, in _get_source_fast
    raise TemplateNotFound(template)
jinja2.exceptions.TemplateNotFound: login.html
2018-07-05 14:57:23,844 ERROR: Exception on /auth/login [GET] [in d:\python_projects\flask\venv\lib\site-packages\flask\app.py:1761]
Traceback (most recent call last):
  File "d:\python_projects\flask\venv\lib\site-packages\flask\app.py", line 2292, in wsgi_app
    response = self.full_dispatch_request()
  File "d:\python_projects\flask\venv\lib\site-packages\flask\app.py", line 1815, in full_dispatch_request
    rv = self.handle_user_exception(e)
  File "d:\python_projects\flask\venv\lib\site-packages\flask\app.py", line 1718, in handle_user_exception
    reraise(exc_type, exc_value, tb)
  File "d:\python_projects\flask\venv\lib\site-packages\flask\_compat.py", line 35, in reraise
    raise value
  File "d:\python_projects\flask\venv\lib\site-packages\flask\app.py", line 1813, in full_dispatch_request
    rv = self.dispatch_request()
  File "d:\python_projects\flask\venv\lib\site-packages\flask\app.py", line 1799, in dispatch_request
    return self.view_functions[rule.endpoint](**req.view_args)
  File "D:\python_projects\flask\app\auth\routes.py", line 26, in login
    return render_template('auth/login.html', title='Sign in', form=form)
  File "d:\python_projects\flask\venv\lib\site-packages\flask\templating.py", line 134, in render_template
    return _render(ctx.app.jinja_env.get_or_select_template(template_name_or_list),
  File "d:\python_projects\flask\venv\lib\site-packages\jinja2\environment.py", line 869, in get_or_select_template
    return self.get_template(template_name_or_list, parent, globals)
  File "d:\python_projects\flask\venv\lib\site-packages\jinja2\environment.py", line 830, in get_template
    return self._load_template(name, self.make_globals(globals))
  File "d:\python_projects\flask\venv\lib\site-packages\jinja2\environment.py", line 804, in _load_template
    template = self.loader.load(self, name, globals)
  File "d:\python_projects\flask\venv\lib\site-packages\jinja2\loaders.py", line 113, in load
    source, filename, uptodate = self.get_source(environment, name)
  File "d:\python_projects\flask\venv\lib\site-packages\flask\templating.py", line 58, in get_source
    return self._get_source_fast(environment, template)
  File "d:\python_projects\flask\venv\lib\site-packages\flask\templating.py", line 86, in _get_source_fast
    raise TemplateNotFound(template)
jinja2.exceptions.TemplateNotFound: login.html
2018-07-05 14:57:40,888 INFO: Microblog startup [in D:\python_projects\flask\app\__init__.py:73]
2018-07-05 14:57:56,672 ERROR: Exception on /index [GET] [in d:\python_projects\flask\venv\lib\site-packages\flask\app.py:1761]
Traceback (most recent call last):
  File "d:\python_projects\flask\venv\lib\site-packages\flask\app.py", line 2292, in wsgi_app
    response = self.full_dispatch_request()
  File "d:\python_projects\flask\venv\lib\site-packages\flask\app.py", line 1815, in full_dispatch_request
    rv = self.handle_user_exception(e)
  File "d:\python_projects\flask\venv\lib\site-packages\flask\app.py", line 1718, in handle_user_exception
    reraise(exc_type, exc_value, tb)
  File "d:\python_projects\flask\venv\lib\site-packages\flask\_compat.py", line 35, in reraise
    raise value
  File "d:\python_projects\flask\venv\lib\site-packages\flask\app.py", line 1813, in full_dispatch_request
    rv = self.dispatch_request()
  File "d:\python_projects\flask\venv\lib\site-packages\flask\app.py", line 1799, in dispatch_request
    return self.view_functions[rule.endpoint](**req.view_args)
  File "d:\python_projects\flask\venv\lib\site-packages\flask_login\utils.py", line 261, in decorated_view
    return func(*args, **kwargs)
  File "D:\python_projects\flask\app\main\routes.py", line 34, in index
    next_url = url_for('index', page=posts.next_num) if posts.has_next else None
  File "d:\python_projects\flask\venv\lib\site-packages\flask\helpers.py", line 356, in url_for
    return appctx.app.handle_url_build_error(error, endpoint, values)
  File "d:\python_projects\flask\venv\lib\site-packages\flask\app.py", line 2061, in handle_url_build_error
    reraise(exc_type, exc_value, tb)
  File "d:\python_projects\flask\venv\lib\site-packages\flask\_compat.py", line 35, in reraise
    raise value
  File "d:\python_projects\flask\venv\lib\site-packages\flask\helpers.py", line 345, in url_for
    force_external=external)
  File "d:\python_projects\flask\venv\lib\site-packages\werkzeug\routing.py", line 1776, in build
    raise BuildError(endpoint, values, method, self)
werkzeug.routing.BuildError: Could not build url for endpoint 'index' with values ['page']. Did you mean 'main.index' instead?
2018-07-05 14:59:53,310 INFO: Microblog startup [in D:\python_projects\flask\app\__init__.py:73]
